Workbook

Sheet Proforma
A2: Cloud Cowboy — 5-Year Proforma (Base Case)
A3: US-only · Operating-system model · 100% ACH capture · marketing grounded in AG-Involvement plan · benefits Jan-2028. Blue = adjustable input.
B4: Year 0 | C4: Year 1 | D4: Year 2 | E4: Year 3 | F4: Year 4 | G4: Year 5
B5: 2026 | C5: 2027 | D5: 2028 | E5: 2029 | F5: 2030 | G5: 2031
I6: KEY ASSUMPTIONS
I7: Avg GMV / customer | J7: 900000
A8: CUSTOMERS & DEMAND | I8: Subscription / yr | J8: 12000
A9: Paying customers (EOY) | B9: 0 | C9: 125 | D9: 300 | E9: 650 | F9: 1250 | G9: 2000 | I9: Take rate | J9: 0.02
A10: Pre-sold (acquired 2026, bill from 2027) | B10: 50 | C10: 0 | D10: 0 | E10: 0 | F10: 0 | G10: 0 | I10: Transaction capture | J10: 1
A11: Pre-season capture % (new adds) | B11: 0 | C11: 0.15 | D11: 0.3 | E11: 0.35 | F11: 0.35 | G11: 0.35 | I11: Jobs / customer / yr | J11: 150
A12: Annual logo churn % | B12: 0 | C12: 0.08 | D12: 0.07 | E12: 0.06 | F12: 0.055 | G12: 0.05 | I12: ACH cost / job | J12: 5
A13: Same-customer GMV growth % | B13: 0 | C13: 0.08 | D13: 0.1 | E13: 0.12 | F13: 0.13 | G13: 0.14 | I13: Layer-1 AI / FTE / yr | J13: 6000
I14: Platform COGS / cust / yr | J14: 1800
A15: MARKETING & CUSTOMER ACQUISITION (grounded plan + scaling digital/national) | I15: Sales commission / new cust | J15: 1200
A16: Social & content (base $10K/mo) | B16: 50000 | C16: 120000 | D16: 120000 | E16: 120000 | F16: 120000 | G16: 120000 | I16: ARR multiple | J16: 20
A17: Digital marketing & paid media | B17: 20000 | C17: 50000 | D17: 140000 | E17: 260000 | F17: 370000 | G17: 450000 | I17: Target all-in CAC | J17: 2500
A18: Event circuit — booth/reg + travel (+10%/yr from 2028) | B18: =Events!$O$31*0.5 | C18: =Events!$O$31*1 | D18: =Events!$O$31*1.1 | E18: =Events!$O$31*1.21 | F18: =Events!$O$31*1.331 | G18: =Events!$O$31*1.4641 | I18: Capital raised (investment) | J18: 1000000
A19: National expansion (regional reps, booths, paid) | B19: 0 | C19: 0 | D19: 120000 | E19: 230000 | F19: 320000 | G19: 390000
A20: Memberships & dues (12 orgs) | B20: ='Orgs & Boards'!$D$17 | C20: ='Orgs & Boards'!$D$17 | D20: ='Orgs & Boards'!$D$17 | E20: ='Orgs & Boards'!$D$17 | F20: ='Orgs & Boards'!$D$17 | G20: ='Orgs & Boards'!$D$17
A21: One-time launch capital (truck/trailer/merch/booth) | B21: =Events!$C$39 | C21: 0 | D21: 0 | E21: 0 | F21: 0 | G21: 0
A22: Total marketing programs | B22: =SUM(B16:B21) -> 239201 | C22: =SUM(C16:C21) -> 266077 | D22: =SUM(D16:D21) -> 485452 | E22: =SUM(E16:E21) -> 725765 | F22: =SUM(F16:F21) -> 937109 | G22: =SUM(G16:G21) -> 1099587
A23: Grounded AG plan (2027 event circuit $93,752 + memberships $2,325 + $10K/mo social); event circuit grows 10%/yr from 2028 as shows are added; digital & national expansion scale with reach. Marketing programs + sales commission = all-in CAC, compressing toward the $2,500 target by Year 5 (see Key Metrics). 2026 one-time $120K = truck $60K + trailer $15K + merch $15K + booth $30K.
A24: GENERAL & ADMINISTRATIVE
A25: G&A (tools, legal, insurance, CRM) | B25: 150000 | C25: 320000 | D25: 580000 | E25: 880000 | F25: 1250000 | G25: 1650000
A27: STAFFING — FTE-years by category
A28: CEO (founder) | B28: 0.42 | C28: 1 | D28: 1 | E28: 1 | F28: 1 | G28: 1
A29: Engineering | B29: 0.83 | C29: 3 | D29: 5 | E29: 7 | F29: 9 | G29: 11
A30: Sales | B30: 0 | C30: 1 | D30: 3 | E30: 6 | F30: 9 | G30: 12
A31: Marketing | B31: 0.25 | C31: 1 | D31: 2 | E31: 3 | F31: 4 | G31: 5
A32: Business Ops | B32: 0.25 | C32: 1 | D32: 2 | E32: 3 | F32: 4 | G32: 5
A33: Customer Success | B33: 0 | C33: 1 | D33: 2 | E33: 4 | F33: 6 | G33: 8
A34: Ag Specialists | B34: 0 | C34: 0.58 | D34: 2 | E34: 3 | F34: 4 | G34: 5
A35: Total FTE-years | B35: =SUM(B28:B34) -> 1.75 | C35: =SUM(C28:C34) -> 8.58 | D35: =SUM(D28:D34) -> 17 | E35: =SUM(E28:E34) -> 27 | F35: =SUM(F28:F34) -> 37 | G35: =SUM(G28:G34) -> 47
A36: STAFFING — avg base salary by category
A37: CEO (founder) | B37: 150000 | C37: 150000 | D37: 175000 | E37: 180000 | F37: 185000 | G37: 190000
A38: Engineering | B38: 70000 | C38: 70000 | D38: 140000 | E38: 145000 | F38: 150000 | G38: 155000
A39: Sales | B39: 60000 | C39: 60000 | D39: 65000 | E39: 70000 | F39: 72000 | G39: 74000
A40: Marketing | B40: 70000 | C40: 70000 | D40: 105000 | E40: 110000 | F40: 115000 | G40: 120000
A41: Business Ops | B41: 70000 | C41: 70000 | D41: 105000 | E41: 110000 | F41: 115000 | G41: 120000
A42: Customer Success | B42: 60000 | C42: 60000 | D42: 70000 | E42: 72000 | F42: 74000 | G42: 76000
...

Sheet Monthly Cash Flow
A2: Cloud Cowboy — Monthly Cash Flow (seasonalized)
A3: Annual base-case totals spread across the real ag spray calendar (Seasonality tab). Revenue, jobs & ACH follow the season; event spend lands in the actual months shows occur (fall/winter-heavy); salaries, G&A, platform, subscription spread evenly; 2026 cost loads Aug-Dec (launch). Monthly columns reconcile exactly to the annual Proforma.
A4: Year | B4: 2026 | N4: 2027 | Z4: 2028 | AL4: 2029 | AX4: 2030 | BJ4: 2031
A5: Month | B5: Jan | C5: Feb | D5: Mar | E5: Apr | F5: May | G5: Jun | H5: Jul | I5: Aug | J5: Sep | K5: Oct | L5: Nov | M5: Dec | N5: Jan | O5: Feb | P5: Mar | Q5: Apr | R5: May | S5: Jun | T5: Jul | U5: Aug | V5: Sep | W5: Oct | X5: Nov | Y5: Dec | Z5: Jan | AA5: Feb | AB5: Mar | AC5: Apr | AD5: May | AE5: Jun | AF5: Jul | AG5: Aug | AH5: Sep | AI5: Oct | AJ5: Nov | AK5: Dec | AL5: Jan | AM5: Feb | AN5: Mar | AO5: Apr | AP5: May | AQ5: Jun | AR5: Jul | AS5: Aug | AT5: Sep | AU5: Oct | AV5: Nov | AW5: Dec | AX5: Jan | AY5: Feb | AZ5: Mar | BA5: Apr | BB5: May | BC5: Jun | BD5: Jul | BE5: Aug | BF5: Sep | BG5: Oct | BH5: Nov | BI5: Dec | BJ5: Jan | BK5: Feb | BL5: Mar | BM5: Apr | BN5: May | BO5: Jun | BP5: Jul | BQ5: Aug | BR5: Sep | BS5: Oct | BT5: Nov | BU5: Dec
A6: Seasonal multiplier | B6: =Seasonality!$B$3 -> 0.05 | C6: =Seasonality!$B$4 -> 0.1 | D6: =Seasonality!$B$5 -> 0.35 | E6: =Seasonality!$B$6 -> 1.5 | F6: =Seasonality!$B$7 -> 2.4 | G6: =Seasonality!$B$8 -> 1.8 | H6: =Seasonality!$B$9 -> 2.4 | I6: =Seasonality!$B$10 -> 1.8 | J6: =Seasonality!$B$11 -> 0.85 | K6: =Seasonality!$B$12 -> 0.5 | L6: =Seasonality!$B$13 -> 0.15 | M6: =Seasonality!$B$14 -> 0.1 | N6: =Seasonality!$B$3 -> 0.05 | O6: =Seasonality!$B$4 -> 0.1 | P6: =Seasonality!$B$5 -> 0.35 | Q6: =Seasonality!$B$6 -> 1.5 | R6: =Seasonality!$B$7 -> 2.4 | S6: =Seasonality!$B$8 -> 1.8 | T6: =Seasonality!$B$9 -> 2.4 | U6: =Seasonality!$B$10 -> 1.8 | V6: =Seasonality!$B$11 -> 0.85 | W6: =Seasonality!$B$12 -> 0.5 | X6: =Seasonality!$B$13 -> 0.15 | Y6: =Seasonality!$B$14 -> 0.1 | Z6: =Seasonality!$B$3 -> 0.05 | AA6: =Seasonality!$B$4 -> 0.1 | AB6: =Seasonality!$B$5 -> 0.35 | AC6: =Seasonality!$B$6 -> 1.5 | AD6: =Seasonality!$B$7 -> 2.4 | AE6: =Seasonality!$B$8 -> 1.8 | AF6: =Seasonality!$B$9 -> 2.4 | AG6: =Seasonality!$B$10 -> 1.8 | AH6: =Seasonality!$B$11 -> 0.85 | AI6: =Seasonality!$B$12 -> 0.5 | AJ6: =Seasonality!$B$13 -> 0.15 | AK6: =Seasonality!$B$14 -> 0.1 | AL6: =Seasonality!$B$3 -> 0.05 | AM6: =Seasonality!$B$4 -> 0.1 | AN6: =Seasonality!$B$5 -> 0.35 | AO6: =Seasonality!$B$6 -> 1.5 | AP6: =Seasonality!$B$7 -> 2.4 | AQ6: =Seasonality!$B$8 -> 1.8 | AR6: =Seasonality!$B$9 -> 2.4 | AS6: =Seasonality!$B$10 -> 1.8 | AT6: =Seasonality!$B$11 -> 0.85 | AU6: =Seasonality!$B$12 -> 0.5 | AV6: =Seasonality!$B$13 -> 0.15 | AW6: =Seasonality!$B$14 -> 0.1 | AX6: =Seasonality!$B$3 -> 0.05 | AY6: =Seasonality!$B$4 -> 0.1 | AZ6: =Seasonality!$B$5 -> 0.35 | BA6: =Seasonality!$B$6 -> 1.5 | BB6: =Seasonality!$B$7 -> 2.4 | BC6: =Seasonality!$B$8 -> 1.8 | BD6: =Seasonality!$B$9 -> 2.4 | BE6: =Seasonality!$B$10 -> 1.8 | BF6: =Seasonality!$B$11 -> 0.85 | BG6: =Seasonality!$B$12 -> 0.5 | BH6: =Seasonality!$B$13 -> 0.15 | BI6: =Seasonality!$B$14 -> 0.1 | BJ6: =Seasonality!$B$3 -> 0.05 | BK6: =Seasonality!$B$4 -> 0.1 | BL6: =Seasonality!$B$5 -> 0.35 | BM6: =Seasonality!$B$6 -> 1.5 | BN6: =Seasonality!$B$7 -> 2.4 | BO6: =Seasonality!$B$8 -> 1.8 | BP6: =Seasonality!$B$9 -> 2.4 | BQ6: =Seasonality!$B$10 -> 1.8 | BR6: =Seasonality!$B$11 -> 0.85 | BS6: =Seasonality!$B$12 -> 0.5 | BT6: =Seasonality!$B$13 -> 0.15 | BU6: =Seasonality!$B$14 -> 0.1
A7: Jobs run (count) | B7: 0 | C7: 0 | D7: 0 | E7: 0 | F7: 0 | G7: 0 | H7: 0 | I7: 0 | J7: 0 | K7: 0 | L7: 0 | M7: 0 | N7: =Proforma!C62*Proforma!$J$11*Seasonality!$B$3/12 -> 38.65625 | O7: =Proforma!C62*Proforma!$J$11*Seasonality!$B$4/12 -> 77.3125 | P7: =Proforma!C62*Proforma!$J$11*Seasonality!$B$5/12 -> 270.59375 | Q7: =Proforma!C62*Proforma!$J$11*Seasonality!$B$6/12 -> 1159.6875 | R7: =Proforma!C62*Proforma!$J$11*Seasonality!$B$7/12 -> 1855.5 | S7: =Proforma!C62*Proforma!$J$11*Seasonality!$B$8/12 -> 1391.625 | T7: =Proforma!C62*Proforma!$J$11*Seasonality!$B$9/12 -> 1855.5 | U7: =Proforma!C62*Proforma!$J$11*Seasonality!$B$10/12 -> 1391.625 | V7: =Proforma!C62*Proforma!$J$11*Seasonality!$B$11/12 -> 657.15625 | W7: =Proforma!C62*Proforma!$J$11*Seasonality!$B$12/12 -> 386.5625 | X7: =Proforma!C62*Proforma!$J$11*Seasonality!$B$13/12 -> 115.96875 | Y7: =Proforma!C62*Proforma!$J$11*Seasonality!$B$14/12 -> 77.3125 | Z7: =Proforma!D62*Proforma!$J$11*Seasonality!$B$3/12 -> 112.57812 | AA7: =Proforma!D62*Proforma!$J$11*Seasonality!$B$4/12 -> 225.15625 | AB7: =Proforma!D62*Proforma!$J$11*Seasonality!$B$5/12 -> 788.04688 | AC7: =Proforma!D62*Proforma!$J$11*Seasonality!$B$6/12 -> 3377.3438 | AD7: =Proforma!D62*Proforma!$J$11*Seasonality!$B$7/12 -> 5403.75 | AE7: =Proforma!D62*Proforma!$J$11*Seasonality!$B$8/12 -> 4052.8125 | AF7: =Proforma!D62*Proforma!$J$11*Seasonality!$B$9/12 -> 5403.75 | AG7: =Proforma!D62*Proforma!$J$11*Seasonality!$B$10/12 -> 4052.8125 | AH7: =Proforma!D62*Proforma!$J$11*Seasonality!$B$11/12 -> 1913.8281 | AI7: =Proforma!D62*Proforma!$J$11*Seasonality!$B$12/12 -> 1125.7812 | AJ7: =Proforma!D62*Proforma!$J$11*Seasonality!$B$13/12 -> 337.73438 | AK7: =Proforma!D62*Proforma!$J$11*Seasonality!$B$14/12 -> 225.15625 | AL7: =Proforma!E62*Proforma!$J$11*Seasonality!$B$3/12 -> 268 | AM7: =Proforma!E62*Proforma!$J$11*Seasonality!$B$4/12 -> 536 | AN7: =Proforma!E62*Proforma!$J$11*Seasonality!$B$5/12 -> 1876 | AO7: =Proforma!E62*Proforma!$J$11*Seasonality!$B$6/12 -> 8040 | AP7: =Proforma!E62*Proforma!$J$11*Seasonality!$B$7/12 -> 12864 | AQ7: =Proforma!E62*Proforma!$J$11*Seasonality!$B$8/12 -> 9648 | AR7: =Proforma!E62*Proforma!$J$11*Seasonality!$B$9/12 -> 12864 | AS7: =Proforma!E62*Proforma!$J$11*Seasonality!$B$10/12 -> 9648 | AT7: =Proforma!E62*Proforma!$J$11*Seasonality!$B$11/12 -> 4556 | AU7: =Proforma!E62*Proforma!$J$11*Seasonality!$B$12/12 -> 2680 | AV7: =Proforma!E62*Proforma!$J$11*Seasonality!$B$13/12 -> 804 | AW7: =Proforma!E62*Proforma!$J$11*Seasonality!$B$14/12 -> 536 | AX7: =Proforma!F62*Proforma!$J$11*Seasonality!$B$3/12 -> 545.32031 | AY7: =Proforma!F62*Proforma!$J$11*Seasonality!$B$4/12 -> 1090.6406 | AZ7: =Proforma!F62*Proforma!$J$11*Seasonality!$B$5/12 -> 3817.2422 | BA7: =Proforma!F62*Proforma!$J$11*Seasonality!$B$6/12 -> 16359.609 | BB7: =Proforma!F62*Proforma!$J$11*Seasonality!$B$7/12 -> 26175.375 | BC7: =Proforma!F62*Proforma!$J$11*Seasonality!$B$8/12 -> 19631.531 | BD7: =Proforma!F62*Proforma!$J$11*Seasonality!$B$9/12 -> 26175.375 | BE7: =Proforma!F62*Proforma!$J$11*Seasonality!$B$10/12 -> 19631.531 | BF7: =Proforma!F62*Proforma!$J$11*Seasonality!$B$11/12 -> 9270.4453 | BG7: =Proforma!F62*Proforma!$J$11*Seasonality!$B$12/12 -> 5453.2031 | BH7: =Proforma!F62*Proforma!$J$11*Seasonality!$B$13/12 -> 1635.9609 | BI7: =Proforma!F62*Proforma!$J$11*Seasonality!$B$14/12 -> 1090.6406 | BJ7: =Proforma!G62*Proforma!$J$11*Seasonality!$B$3/12 -> 958.98438 | BK7: =Proforma!G62*Proforma!$J$11*Seasonality!$B$4/12 -> 1917.9688 | BL7: =Proforma!G62*Proforma!$J$11*Seasonality!$B$5/12 -> 6712.8906 | BM7: =Proforma!G62*Proforma!$J$11*Seasonality!$B$6/12 -> 28769.531 | BN7: =Proforma!G62*Proforma!$J$11*Seasonality!$B$7/12 -> 46031.25 | BO7: =Proforma!G62*Proforma!$J$11*Seasonality!$B$8/12 -> 34523.438 | BP7: =Proforma!G62*Proforma!$J$11*Seasonality!$B$9/12 -> 46031.25 | BQ7: =Proforma!G62*Proforma!$J$11*Seasonality!$B$10/12 -> 34523.438 | BR7: =Proforma!G62*Proforma!$J$11*Seasonality!$B$11/12 -> 16302.734 | BS7: =Proforma!G62*Proforma!$J$11*Seasonality!$B$12/12 -> 9589.8438 | BT7: =Proforma!G62*Proforma!$J$11*Seasonality!$B$13/12 -> 2876.9531 | BU7: =Proforma!G62*Proforma!$J$11*Seasonality!$B$14/12 -> 1917.9688
A9: Subscription revenue | B9: 0 | C9: 0 | D9: 0 | E9: 0 | F9: 0 | G9: 0 | H9: 0 | I9: 0 | J9: 0 | K9: 0 | L9: 0 | M9: 0 | N9: =Proforma!C63/12 -> 61850 | O9: =Proforma!C63/12 -> 61850 | P9: =Proforma!C63/12 -> 61850 | Q9: =Proforma!C63/12 -> 61850 | R9: =Proforma!C63/12 -> 61850 | S9: =Proforma!C63/12 -> 61850 | T9: =Proforma!C63/12 -> 61850 | U9: =Proforma!C63/12 -> 61850 | V9: =Proforma!C63/12 -> 61850 | W9: =Proforma!C63/12 -> 61850 | X9: =Proforma!C63/12 -> 61850 | Y9: =Proforma!C63/12 -> 61850 | Z9: =Proforma!D63/12 -> 180125 | AA9: =Proforma!D63/12 -> 180125 | AB9: =Proforma!D63/12 -> 180125 | AC9: =Proforma!D63/12 -> 180125 | AD9: =Proforma!D63/12 -> 180125 | AE9: =Proforma!D63/12 -> 180125 | AF9: =Proforma!D63/12 -> 180125 | AG9: =Proforma!D63/12 -> 180125 | AH9: =Proforma!D63/12 -> 180125 | AI9: =Proforma!D63/12 -> 180125 | AJ9: =Proforma!D63/12 -> 180125 | AK9: =Proforma!D63/12 -> 180125 | AL9: =Proforma!E63/12 -> 428800 | AM9: =Proforma!E63/12 -> 428800 | AN9: =Proforma!E63/12 -> 428800 | AO9: =Proforma!E63/12 -> 428800 | AP9: =Proforma!E63/12 -> 428800 | AQ9: =Proforma!E63/12 -> 428800 | AR9: =Proforma!E63/12 -> 428800 | AS9: =Proforma!E63/12 -> 428800 | AT9: =Proforma!E63/12 -> 428800 | AU9: =Proforma!E63/12 -> 428800 | AV9: =Proforma!E63/12 -> 428800 | AW9: =Proforma!E63/12 -> 428800 | AX9: =Proforma!F63/12 -> 872512.5 | AY9: =Proforma!F63/12 -> 872512.5 | AZ9: =Proforma!F63/12 -> 872512.5 | BA9: =Proforma!F63/12 -> 872512.5 | BB9: =Proforma!F63/12 -> 872512.5 | BC9: =Proforma!F63/12 -> 872512.5 | BD9: =Proforma!F63/12 -> 872512.5 | BE9: =Proforma!F63/12 -> 872512.5 | BF9: =Proforma!F63/12 -> 872512.5 | BG9: =Proforma!F63/12 -> 872512.5 | BH9: =Proforma!F63/12 -> 872512.5 | BI9: =Proforma!F63/12 -> 872512.5 | BJ9: =Proforma!G63/12 -> 1534375 | BK9: =Proforma!G63/12 -> 1534375 | BL9: =Proforma!G63/12 -> 1534375 | BM9: =Proforma!G63/12 -> 1534375 | BN9: =Proforma!G63/12 -> 1534375 | BO9: =Proforma!G63/12 -> 1534375 | BP9: =Proforma!G63/12 -> 1534375 | BQ9: =Proforma!G63/12 -> 1534375 | BR9: =Proforma!G63/12 -> 1534375 | BS9: =Proforma!G63/12 -> 1534375 | BT9: =Proforma!G63/12 -> 1534375 | BU9: =Proforma!G63/12 -> 1534375
A10: Transaction revenue (seasonal) | B10: 0 | C10: 0 | D10: 0 | E10: 0 | F10: 0 | G10: 0 | H10: 0 | I10: 0 | J10: 0 | K10: 0 | L10: 0 | M10: 0 | N10: =Proforma!C64*Seasonality!$B$3/12 -> 4638.75 | O10: =Proforma!C64*Seasonality!$B$4/12 -> 9277.5 | P10: =Proforma!C64*Seasonality!$B$5/12 -> 32471.25 | Q10: =Proforma!C64*Seasonality!$B$6/12 -> 139162.5 | R10: =Proforma!C64*Seasonality!$B$7/12 -> 222660 | S10: =Proforma!C64*Seasonality!$B$8/12 -> 166995 | T10: =Proforma!C64*Seasonality!$B$9/12 -> 222660 | U10: =Proforma!C64*Seasonality!$B$10/12 -> 166995 | V10: =Proforma!C64*Seasonality!$B$11/12 -> 78858.75 | W10: =Proforma!C64*Seasonality!$B$12/12 -> 46387.5 | X10: =Proforma!C64*Seasonality!$B$13/12 -> 13916.25 | Y10: =Proforma!C64*Seasonality!$B$14/12 -> 9277.5 | Z10: =Proforma!D64*Seasonality!$B$3/12 -> 13509.375 | AA10: =Proforma!D64*Seasonality!$B$4/12 -> 27018.75 | AB10: =Proforma!D64*Seasonality!$B$5/12 -> 94565.625 | AC10: =Proforma!D64*Seasonality!$B$6/12 -> 405281.25 | AD10: =Proforma!D64*Seasonality!$B$7/12 -> 648450 | AE10: =Proforma!D64*Seasonality!$B$8/12 -> 486337.5 | AF10: =Proforma!D64*Seasonality!$B$9/12 -> 648450 | AG10: =Proforma!D64*Seasonality!$B$10/12 -> 486337.5 | AH10: =Proforma!D64*Seasonality!$B$11/12 -> 229659.38 | AI10: =Proforma!D64*Seasonality!$B$12/12 -> 135093.75 | AJ10: =Proforma!D64*Seasonality!$B$13/12 -> 40528.125 | AK10: =Proforma!D64*Seasonality!$B$14/12 -> 27018.75 | AL10: =Proforma!E64*Seasonality!$B$3/12 -> 32160 | AM10: =Proforma!E64*Seasonality!$B$4/12 -> 64320 | AN10: =Proforma!E64*Seasonality!$B$5/12 -> 225120 | AO10: =Proforma!E64*Seasonality!$B$6/12 -> 964800 | AP10: =Proforma!E64*Seasonality!$B$7/12 -> 1543680 | AQ10: =Proforma!E64*Seasonality!$B$8/12 -> 1157760 | AR10: =Proforma!E64*Seasonality!$B$9/12 -> 1543680 | AS10: =Proforma!E64*Seasonality!$B$10/12 -> 1157760 | AT10: =Proforma!E64*Seasonality!$B$11/12 -> 546720 | AU10: =Proforma!E64*Seasonality!$B$12/12 -> 321600 | AV10: =Proforma!E64*Seasonality!$B$13/12 -> 96480 | AW10: =Proforma!E64*Seasonality!$B$14/12 -> 64320 | AX10: =Proforma!F64*Seasonality!$B$3/12 -> 65438.438 | AY10: =Proforma!F64*Seasonality!$B$4/12 -> 130876.88 | AZ10: =Proforma!F64*Seasonality!$B$5/12 -> 458069.06 | BA10: =Proforma!F64*Seasonality!$B$6/12 -> 1963153.1 | BB10: =Proforma!F64*Seasonality!$B$7/12 -> 3141045 | BC10: =Proforma!F64*Seasonality!$B$8/12 -> 2355783.8 | BD10: =Proforma!F64*Seasonality!$B$9/12 -> 3141045 | BE10: =Proforma!F64*Seasonality!$B$10/12 -> 2355783.8 | BF10: =Proforma!F64*Seasonality!$B$11/12 -> 1112453.4 | BG10: =Proforma!F64*Seasonality!$B$12/12 -> 654384.38 | BH10: =Proforma!F64*Seasonality!$B$13/12 -> 196315.31 | BI10: =Proforma!F64*Seasonality!$B$14/12 -> 130876.88 | BJ10: =Proforma!G64*Seasonality!$B$3/12 -> 115078.12 | BK10: =Proforma!G64*Seasonality!$B$4/12 -> 230156.25 | BL10: =Proforma!G64*Seasonality!$B$5/12 -> 805546.88 | BM10: =Proforma!G64*Seasonality!$B$6/12 -> 3452343.8 | BN10: =Proforma!G64*Seasonality!$B$7/12 -> 5523750 | BO10: =Proforma!G64*Seasonality!$B$8/12 -> 4142812.5 | BP10: =Proforma!G64*Seasonality!$B$9/12 -> 5523750 | BQ10: =Proforma!G64*Seasonality!$B$10/12 -> 4142812.5 | BR10: =Proforma!G64*Seasonality!$B$11/12 -> 1956328.1 | BS10: =Proforma!G64*Seasonality!$B$12/12 -> 1150781.2 | BT10: =Proforma!G64*Seasonality!$B$13/12 -> 345234.38 | BU10: =Proforma!G64*Seasonality!$B$14/12 -> 230156.25
A11: TOTAL REVENUE | B11: =B9+B10 -> 0 | C11: =C9+C10 -> 0 | D11: =D9+D10 -> 0 | E11: =E9+E10 -> 0 | F11: =F9+F10 -> 0 | G11: =G9+G10 -> 0 | H11: =H9+H10 -> 0 | I11: =I9+I10 -> 0 | ... BU11: =BU9+BU10 -> 1764531.2
A13: Payment processing (ACH) | B13: =Proforma!B68*Seasonality!$B$3/12 -> 0 | C13: =Proforma!B68*Seasonality!$B$4/12 -> 0 | D13: =Proforma!B68*Seasonality!$B$5/12 -> 0 | E13: =Proforma!B68*Seasonality!$B$6/12 -> 0 | F13: =Proforma!B68*Seasonality!$B$7/12 -> 0 | G13: =Proforma!B68*Seasonality!$B$8/12 -> 0 | H13: =Proforma!B68*Seasonality!$B$9/12 -> 0 | I13: =Proforma!B68*Seasonality!$B$10/12 -> 0 | J13: =Proforma!B68*Seasonality!$B$11/12 -> 0 | K13: =Proforma!B68*Seasonality!$B$12/12 -> 0 | L13: =Proforma!B68*Seasonality!$B$13/12 -> 0 | M13: =Proforma!B68*Seasonality!$B$14/12 -> 0 | N13: =Proforma!C68*Seasonality!$B$3/12 -> -193.28125 | O13: =Proforma!C68*Seasonality!$B$4/12 -> -386.5625 | P13: =Proforma!C68*Seasonality!$B$5/12 -> -1352.9687 | Q13: =Proforma!C68*Seasonality!$B$6/12 -> -5798.4375 | R13: =Proforma!C68*Seasonality!$B$7/12 -> -9277.5 | S13: =Proforma!C68*Seasonality!$B$8/12 -> -6958.125 | T13: =Proforma!C68*Seasonality!$B$9/12 -> -9277.5 | U13: =Proforma!C68*Seasonality!$B$10/12 -> -6958.125 | V13: =Proforma!C68*Seasonality!$B$11/12 -> -3285.7812 | W13: =Proforma!C68*Seasonality!$B$12/12 -> -1932.8125 | X13: =Proforma!C68*Seasonality!$B$13/12 -> -579.84375 | Y13: =Proforma!C68*Seasonality!$B$14/12 -> -386.5625 | Z13: =Proforma!D68*Seasonality!$B$3/12 -> -562.89062 | AA13: =Proforma!D68*Seasonality!$B$4/12 -> -1125.7812 | AB13: =Proforma!D68*Seasonality!$B$5/12 -> -3940.2344 | AC13: =Proforma!D68*Seasonality!$B$6/12 -> -16886.719 | AD13: =Proforma!D68*Seasonality!$B$7/12 -> -27018.75 | AE13: =Proforma!D68*Seasonality!$B$8/12 -> -20264.062 | AF13: =Proforma!D68*Seasonality!$B$9/12 -> -27018.75 | AG13: =Proforma!D68*Seasonality!$B$10/12 -> -20264.062 | AH13: =Proforma!D68*Seasonality!$B$11/12 -> -9569.1406 | AI13: =Proforma!D68*Seasonality!$B$12/12 -> -5628.9062 | AJ13: =Proforma!D68*Seasonality!$B$13/12 -> -1688.6719 | AK13: =Proforma!D68*Seasonality!$B$14/12 -> -1125.7812 | AL13: =Proforma!E68*Seasonality!$B$3/12 -> -1340 | AM13: =Proforma!E68*Seasonality!$B$4/12 -> -2680 | AN13: =Proforma!E68*Seasonality!$B$5/12 -> -9380 | AO13: =Proforma!E68*Seasonality!$B$6/12 -> -40200 | AP13: =Proforma!E68*Seasonality!$B$7/12 -> -64320 | AQ13: =Proforma!E68*Seasonality!$B$8/12 -> -48240 | AR13: =Proforma!E68*Seasonality!$B$9/12 -> -64320 | AS13: =Proforma!E68*Seasonality!$B$10/12 -> -48240 | AT13: =Proforma!E68*Seasonality!$B$11/12 -> -22780 | AU13: =Proforma!E68*Seasonality!$B$12/12 -> -13400 | AV13: =Proforma!E68*Seasonality!$B$13/12 -> -4020 | AW13: =Proforma!E68*Seasonality!$B$14/12 -> -2680 | AX13: =Proforma!F68*Seasonality!$B$3/12 -> -2726.6016 | AY13: =Proforma!F68*Seasonality!$B$4/12 -> -5453.2031 | AZ13: =Proforma!F68*Seasonality!$B$5/12 -> -19086.211 | BA13: =Proforma!F68*Seasonality!$B$6/12 -> -81798.047 | BB13: =Proforma!F68*Seasonality!$B$7/12 -> -130876.88 | BC13: =Proforma!F68*Seasonality!$B$8/12 -> -98157.656 | BD13: =Proforma!F68*Seasonality!$B$9/12 -> -130876.88 | BE13: =Proforma!F68*Seasonality!$B$10/12 -> -98157.656 | BF13: =Proforma!F68*Seasonality!$B$11/12 -> -46352.227 | BG13: =Proforma!F68*Seasonality!$B$12/12 -> -27266.016 | BH13: =Proforma!F68*Seasonality!$B$13/12 -> -8179.8047 | BI13: =Proforma!F68*Seasonality!$B$14/12 -> -5453.2031 | BJ13: =Proforma!G68*Seasonality!$B$3/12 -> -4794.9219 | BK13: =Proforma!G68*Seasonality!$B$4/12 -> -9589.8438 | BL13: =Proforma!G68*Seasonality!$B$5/12 -> -33564.453 | BM13: =Proforma!G68*Seasonality!$B$6/12 -> -143847.66 | BN13: =Proforma!G68*Seasonality!$B$7/12 -> -230156.25 | BO13: =Proforma!G68*Seasonality!$B$8/12 -> -172617.19 | BP13: =Proforma!G68*Seasonality!$B$9/12 -> -230156.25 | BQ13: =Proforma!G68*Seasonality!$B$10/12 -> -172617.19 | BR13: =Proforma!G68*Seasonality!$B$11/12 -> -81513.672 | BS13: =Proforma!G68*Seasonality!$B$12/12 -> -47949.219 | BT13: =Proforma!G68*Seasonality!$B$13/12 -> -14384.766 | BU13: =Proforma!G68*Seasonality!$B$14/12 -> -9589.8438
A14: Platform (AI + AWS) | B14: =Proforma!B69/12 -> 0 | C14: =Proforma!B69/12 -> 0 | D14: =Proforma!B69/12 -> 0 | E14: =Proforma!B69/12 -> 0 | F14: =Proforma!B69/12 -> 0 | G14: =Proforma!B69/12 -> 0 | H14: =Proforma!B69/12 -> 0 | I14: =Proforma!B69/12 -> 0 | J14: =Proforma!B69/12 -> 0 | K14: =Proforma!B69/12 -> 0 | L14: =Proforma!B69/12 -> 0 | M14: =Proforma!B69/12 -> 0 | N14: =Proforma!C69/12 -> -9277.5 | O14: =Proforma!C69/12 -> -9277.5 | P14: =Proforma!C69/12 -> -9277.5 | Q14: =Proforma!C69/12 -> -9277.5 | R14: =Proforma!C69/12 -> -9277.5 | S14: =Proforma!C69/12 -> -9277.5 | T14: =Proforma!C69/12 -> -9277.5 | U14: =Proforma!C69/12 -> -9277.5 | V14: =Proforma!C69/12 -> -9277.5 | W14: =Proforma!C69/12 -> -9277.5 | X14: =Proforma!C69/12 -> -9277.5 | Y14: =Proforma!C69/12 -> -9277.5 | Z14: =Proforma!D69/12 -> -27018.75 | AA14: =Proforma!D69/12 -> -27018.75 | AB14: =Proforma!D69/12 -> -27018.75 | AC14: =Proforma!D69/12 -> -27018.75 | AD14: =Proforma!D69/12 -> -27018.75 | AE14: =Proforma!D69/12 -> -27018.75 | AF14: =Proforma!D69/12 -> -27018.75 | AG14: =Proforma!D69/12 -> -27018.75 | AH14: =Proforma!D69/12 -> -27018.75 | AI14: =Proforma!D69/12 -> -27018.75 | AJ14: =Proforma!D69/12 -> -27018.75 | AK14: =Proforma!D69/12 -> -27018.75 | AL14: =Proforma!E69/12 -> -64320 | AM14: =Proforma!E69/12 -> -64320 | AN14: =Proforma!E69/12 -> -64320 | AO14: =Proforma!E69/12 -> -64320 | AP14: =Proforma!E69/12 -> -64320 | AQ14: =Proforma!E69/12 -> -64320 | AR14: =Proforma!E69/12 -> -64320 | AS14: =Proforma!E69/12 -> -64320 | AT14: =Proforma!E69/12 -> -64320 | AU14: =Proforma!E69/12 -> -64320 | AV14: =Proforma!E69/12 -> -64320 | AW14: =Proforma!E69/12 -> -64320 | AX14: =Proforma!F69/12 -> -130876.88 | AY14: =Proforma!F69/12 -> -130876.88 | AZ14: =Proforma!F69/12 -> -130876.88 | BA14: =Proforma!F69/12 -> -130876.88 | BB14: =Proforma!F69/12 -> -130876.88 | BC14: =Proforma!F69/12 -> -130876.88 | BD14: =Proforma!F69/12 -> -130876.88 | BE14: =Proforma!F69/12 -> -130876.88 | BF14: =Proforma!F69/12 -> -130876.88 | BG14: =Proforma!F69/12 -> -130876.88 | BH14: =Proforma!F69/12 -> -130876.88 | BI14: =Proforma!F69/12 -> -130876.88 | BJ14: =Proforma!G69/12 -> -230156.25 | BK14: =Proforma!G69/12 -> -230156.25 | BL14: =Proforma!G69/12 -> -230156.25 | BM14: =Proforma!G69/12 -> -230156.25 | BN14: =Proforma!G69/12 -> -230156.25 | BO14: =Proforma!G69/12 -> -230156.25 | BP14: =Proforma!G69/12 -> -230156.25 | BQ14: =Proforma!G69/12 -> -230156.25 | BR14: =Proforma!G69/12 -> -230156.25 | BS14: =Proforma!G69/12 -> -230156.25 | BT14: =Proforma!G69/12 -> -230156.25 | BU14: =Proforma!G69/12 -> -230156.25
A15: People | B15: 0 | C15: 0 | D15: 0 | E15: 0 | F15: 0 | G15: 0 | H15: 0 | I15: =-Proforma!B55/5 -> -34342 | J15: =-Proforma!B55/5 -> -34342 | K15: =-Proforma!B55/5 -> -34342 | L15: =-Proforma!B55/5 -> -34342 | M15: =-Proforma!B55/5 -> -34342 | N15: =-Proforma!C55/12 -> -60555 | O15: =-Proforma!C55/12 -> -60555 | P15: =-Proforma!C55/12 -> -60555 | Q15: =-Proforma!C55/12 -> -60555 | R15: =-Proforma!C55/12 -> -60555 | S15: =-Proforma!C55/12 -> -60555 | T15: =-Proforma!C55/12 -> -60555 | U15: =-Proforma!C55/12 -> -60555 | V15: =-Proforma!C55/12 -> -60555 | W15: =-Proforma!C55/12 -> -60555 | X15: =-Proforma!C55/12 -> -60555 | Y15: =-Proforma!C55/12 -> -60555 | Z15: =-Proforma!D55/12 -> -194133.33 | AA15: =-Proforma!D55/12 -> -194133.33 | AB15: =-Proforma!D55/12 -> -194133.33 | AC15: =-Proforma!D55/12 -> -194133.33 | AD15: =-Proforma!D55/12 -> -194133.33 | AE15: =-Proforma!D55/12 -> -194133.33 | AF15: =-Proforma!D55/12 -> -194133.33 | AG15: =-Proforma!D55/12 -> -194133.33 | AH15: =-Proforma!D55/12 -> -194133.33 | AI15: =-Proforma!D55/12 -> -194133.33 | AJ15: =-Proforma!D55/12 -> -194133.33 | AK15: =-Proforma!D55/12 -> -194133.33 | AL15: =-Proforma!E55/12 -> -305386.67 | AM15: =-Proforma!E55/12 -> -305386.67 | AN15: =-Proforma!E55/12 -> -305386.67 | AO15: =-Proforma!E55/12 -> -305386.67 | AP15: =-Proforma!E55/12 -> -305386.67 | AQ15: =-Proforma!E55/12 -> -305386.67 | AR15: =-Proforma!E55/12 -> -305386.67 | AS15: =-Proforma!E55/12 -> -305386.67 | AT15: =-Proforma!E55/12 -> -305386.67 | AU15: =-Proforma!E55/12 -> -305386.67 | AV15: =-Proforma!E55/12 -> -305386.67 | AW15: =-Proforma!E55/12 -> -305386.67 | AX15: =-Proforma!F55/12 -> -423146.67 | AY15: =-Proforma!F55/12 -> -423146.67 | AZ15: =-Proforma!F55/12 -> -423146.67 | BA15: =-Proforma!F55/12 -> -423146.67 | BB15: =-Proforma!F55/12 -> -423146.67 | BC15: =-Proforma!F55/12 -> -423146.67 | BD15: =-Proforma!F55/12 -> -423146.67 | BE15: =-Proforma!F55/12 -> -423146.67 | BF15: =-Proforma!F55/12 -> -423146.67 | BG15: =-Proforma!F55/12 -> -423146.67 | BH15: =-Proforma!F55/12 -> -423146.67 | BI15: =-Proforma!F55/12 -> -423146.67 | BJ15: =-Proforma!G55/12 -> -548373.33 | BK15: =-Proforma!G55/12 -> -548373.33 | BL15: =-Proforma!G55/12 -> -548373.33 | BM15: =-Proforma!G55/12 -> -548373.33 | BN15: =-Proforma!G55/12 -> -548373.33 | BO15: =-Proforma!G55/12 -> -548373.33 | BP15: =-Proforma!G55/12 -> -548373.33 | BQ15: =-Proforma!G55/12 -> -548373.33 | BR15: =-Proforma!G55/12 -> -548373.33 | BS15: =-Proforma!G55/12 -> -548373.33 | BT15: =-Proforma!G55/12 -> -548373.33 | BU15: =-Proforma!G55/12 -> -548373.33
A16: Layer-1 AI tooling | B16: 0 | C16: 0 | D16: 0 | E16: 0 | F16: 0 | G16: 0 | H16: 0 | I16: =-Proforma!B35*Proforma!$J$13/5 -> -2100 | J16: =-Proforma!B35*Proforma!$J$13/5 -> -2100 | K16: =-Proforma!B35*Proforma!$J$13/5 -> -2100 | L16: =-Proforma!B35*Proforma!$J$13/5 -> -2100 | M16: =-Proforma!B35*Proforma!$J$13/5 -> -2100 | N16: =-Proforma!C35*Proforma!$J$13/12 -> -4290 | O16: =-Proforma!C35*Proforma!$J$13/12 -> -4290 | P16: =-Proforma!C35*Proforma!$J$13/12 -> -4290 | Q16: =-Proforma!C35*Proforma!$J$13/12 -> -4290 | R16: =-Proforma!C35*Proforma!$J$13/12 -> -4290 | S16: =-Proforma!C35*Proforma!$J$13/12 -> -4290 | T16: =-Proforma!C35*Proforma!$J$13/12 -> -4290 | U16: =-Proforma!C35*Proforma!$J$13/12 -> -4290 | V16: =-Proforma!C35*Proforma!$J$13/12 -> -4290 | W16: =-Proforma!C35*Proforma!$J$13/12 -> -4290 | X16: =-Proforma!C35*Proforma!$J$13/12 -> -4290 | Y16: =-Proforma!C35*Proforma!$J$13/12 -> -4290 | Z16: =-Proforma!D35*Proforma!$J$13/12 -> -8500 | AA16: =-Proforma!D35*Proforma!$J$13/12 -> -8500 | AB16: =-Proforma!D35*Proforma!$J$13/12 -> -8500 | AC16: =-Proforma!D35*Proforma!$J$13/12 -> -8500 | AD16: =-Proforma!D35*Proforma!$J$13/12 -> -8500 | AE16: =-Proforma!D35*Proforma!$J$13/12 -> -8500 | AF16: =-Proforma!D35*Proforma!$J$13/12 -> -8500 | AG16: =-Proforma!D35*Proforma!$J$13/12 -> -8500 | AH16: =-Proforma!D35*Proforma!$J$13/12 -> -8500 | AI16: =-Proforma!D35*Proforma!$J$13/12 -> -8500 | AJ16: =-Proforma!D35*Proforma!$J$13/12 -> -8500 | AK16: =-Proforma!D35*Proforma!$J$13/12 -> -8500 | AL16: =-Proforma!E35*Proforma!$J$13/12 -> -13500 | AM16: =-Proforma!E35*Proforma!$J$13/12 -> -13500 | AN16: =-Proforma!E35*Proforma!$J$13/12 -> -13500 | AO16: =-Proforma!E35*Proforma!$J$13/12 -> -13500 | AP16: =-Proforma!E35*Proforma!$J$13/12 -> -13500 | AQ16: =-Proforma!E35*Proforma!$J$13/12 -> -13500 | AR16: =-Proforma!E35*Proforma!$J$13/12 -> -13500 | AS16: =-Proforma!E35*Proforma!$J$13/12 -> -13500 | AT16: =-Proforma!E35*Proforma!$J$13/12 -> -13500 | AU16: =-Proforma!E35*Proforma!$J$13/12 -> -13500 | AV16: =-Proforma!E35*Proforma!$J$13/12 -> -13500 | AW16: =-Proforma!E35*Proforma!$J$13/12 -> -13500 | AX16: =-Proforma!F35*Proforma!$J$13/12 -> -18500 | AY16: =-Proforma!F35*Proforma!$J$13/12 -> -18500 | AZ16: =-Proforma!F35*Proforma!$J$13/12 -> -18500 | BA16: =-Proforma!F35*Proforma!$J$13/12 -> -18500 | BB16: =-Proforma!F35*Proforma!$J$13/12 -> -18500 | BC16: =-Proforma!F35*Proforma!$J$13/12 -> -18500 | BD16: =-Proforma!F35*Proforma!$J$13/12 -> -18500 | BE16: =-Proforma!F35*Proforma!$J$13/12 -> -18500 | BF16: =-Proforma!F35*Proforma!$J$13/12 -> -18500 | BG16: =-Proforma!F35*Proforma!$J$13/12 -> -18500 | BH16: =-Proforma!F35*Proforma!$J$13/12 -> -18500 | BI16: =-Proforma!F35*Proforma!$J$13/12 -> -18500 | BJ16: =-Proforma!G35*Proforma!$J$13/12 -> -23500 | BK16: =-Proforma!G35*Proforma!$J$13/12 -> -23500 | BL16: =-Proforma!G35*Proforma!$J$13/12 -> -23500 | BM16: =-Proforma!G35*Proforma!$J$13/12 -> -23500 | BN16: =-Proforma!G35*Proforma!$J$13/12 -> -23500 | BO16: =-Proforma!G35*Proforma!$J$13/12 -> -23500 | BP16: =-Proforma!G35*Proforma!$J$13/12 -> -23500 | BQ16: =-Proforma!G35*Proforma!$J$13/12 -> -23500 | BR16: =-Proforma!G35*Proforma!$J$13/12 -> -23500 | BS16: =-Proforma!G35*Proforma!$J$13/12 -> -23500 | BT16: =-Proforma!G35*Proforma!$J$13/12 -> -23500 | BU16: =-Proforma!G35*Proforma!$J$13/12 -> -23500
A17: Sales commission | B17: 0 | C17: 0 | D17: 0 | E17: 0 | F17: 0 | G17: 0 | H17: 0 | I17: =Proforma!B77/5 -> -12000 | J17: =Proforma!B77/5 -> -12000 | K17: =Proforma!B77/5 -> -12000 | L17: =Proforma!B77/5 -> -12000 | M17: =Proforma!B77/5 -> -12000 | N17: =Proforma!C77/12 -> -7900 | O17: =Proforma!C77/12 -> -7900 | P17: =Proforma!C77/12 -> -7900 | Q17: =Proforma!C77/12 -> -7900 | R17: =Proforma!C77/12 -> -7900 | S17: =Proforma!C77/12 -> -7900 | T17: =Proforma!C77/12 -> -7900 | U17: =Proforma!C77/12 -> -7900 | V17: =Proforma!C77/12 -> -7900 | W17: =Proforma!C77/12 -> -7900 | X17: =Proforma!C77/12 -> -7900 | Y17: =Proforma!C77/12 -> -7900 | Z17: =Proforma!D77/12 -> -18375 | AA17: =Proforma!D77/12 -> -18375 | AB17: =Proforma!D77/12 -> -18375 | AC17: =Proforma!D77/12 -> -18375 | AD17: =Proforma!D77/12 -> -18375 | AE17: =Proforma!D77/12 -> -18375 | AF17: =Proforma!D77/12 -> -18375 | AG17: =Proforma!D77/12 -> -18375 | AH17: =Proforma!D77/12 -> -18375 | AI17: =Proforma!D77/12 -> -18375 | AJ17: =Proforma!D77/12 -> -18375 | AK17: =Proforma!D77/12 -> -18375 | AL17: =Proforma!E77/12 -> -36800 | AM17: =Proforma!E77/12 -> -36800 | AN17: =Proforma!E77/12 -> -36800 | AO17: =Proforma!E77/12 -> -36800 | AP17: =Proforma!E77/12 -> -36800 | AQ17: =Proforma!E77/12 -> -36800 | AR17: =Proforma!E77/12 -> -36800 | AS17: =Proforma!E77/12 -> -36800 | AT17: =Proforma!E77/12 -> -36800 | AU17: =Proforma!E77/12 -> -36800 | AV17: =Proforma!E77/12 -> -36800 | AW17: =Proforma!E77/12 -> -36800 | AX17: =Proforma!F77/12 -> -63575 | AY17: =Proforma!F77/12 -> -63575 | AZ17: =Proforma!F77/12 -> -63575 | BA17: =Proforma!F77/12 -> -63575 | BB17: =Proforma!F77/12 -> -63575 | BC17: =Proforma!F77/12 -> -63575 | BD17: =Proforma!F77/12 -> -63575 | BE17: =Proforma!F77/12 -> -63575 | BF17: =Proforma!F77/12 -> -63575 | BG17: =Proforma!F77/12 -> -63575 | BH17: =Proforma!F77/12 -> -63575 | BI17: =Proforma!F77/12 -> -63575 | BJ17: =Proforma!G77/12 -> -81250 | BK17: =Proforma!G77/12 -> -81250 | BL17: =Proforma!G77/12 -> -81250 | BM17: =Proforma!G77/12 -> -81250 | BN17: =Proforma!G77/12 -> -81250 | BO17: =Proforma!G77/12 -> -81250 | BP17: =Proforma!G77/12 -> -81250 | BQ17: =Proforma!G77/12 -> -81250 | BR17: =Proforma!G77/12 -> -81250 | BS17: =Proforma!G77/12 -> -81250 | BT17: =Proforma!G77/12 -> -81250 | BU17: =Proforma!G77/12 -> -81250
A18: Marketing — events (scheduled) | B18: 0 | C18: 0 | D18: 0 | E18: 0 | F18: 0 | G18: 0 | H18: 0 | I18: =-Proforma!B18*0.0385 -> -1804.726 | J18: =-Proforma!B18*0.5422 -> -25416.167 | K18: =-Proforma!B18*0.2475 -> -11601.81 | L18: =-Proforma!B18*0.0365 -> -1710.974 | M18: =-Proforma!B18*0.1353 -> -6342.3228 | N18: =-Proforma!C18*Seasonality!$E$3 -> -3928.2088 | O18: =-Proforma!C18*Seasonality!$E$4 -> -10500.224 | P18: =-Proforma!C18*Seasonality!$E$5 -> -10500.224 | Q18: =-Proforma!C18*Seasonality!$E$6 -> 0 | R18: =-Proforma!C18*Seasonality!$E$7 -> -12000.256 | S18: =-Proforma!C18*Seasonality!$E$8 -> -834.3928 | T18: =-Proforma!C18*Seasonality!$E$9 -> 0 | U18: =-Proforma!C18*Seasonality!$E$10 -> -2156.296 | V18: =-Proforma!C18*Seasonality!$E$11 -> -30356.898 | W18: =-Proforma!C18*Seasonality!$E$12 -> -13856.546 | X18: =-Proforma!C18*Seasonality!$E$13 -> -2043.7936 | Y18: =-Proforma!C18*Seasonality!$E$14 -> -7575.1616 | Z18: =-Proforma!D18*Seasonality!$E$3 -> -4321.0213 | AA18: =-Proforma!D18*Seasonality!$E$4 -> -11550.224 | AB18: =-Proforma!D18*Seasonality!$E$5 -> -11550.224 | AC18: =-Proforma!D18*Seasonality!$E$6 -> 0 | AD18: =-Proforma!D18*Seasonality!$E$7 -> -13200.256 | AE18: =-Proforma!D18*Seasonality!$E$8 -> -917.8303 | AF18: =-Proforma!D18*Seasonality!$E$9 -> 0 | AG18: =-Proforma!D18*Seasonality!$E$10 -> -2371.921 | AH18: =-Proforma!D18*Seasonality!$E$11 -> -33392.523 | AI18: =-Proforma!D18*Seasonality!$E$12 -> -15242.171 | AJ18: =-Proforma!D18*Seasonality!$E$13 -> -2248.1686 | AK18: =-Proforma!D18*Seasonality!$E$14 -> -8332.6616 | AL18: =-Proforma!E18*Seasonality!$E$3 -> -4753.136 | AM18: =-Proforma!E18*Seasonality!$E$4 -> -12705.28 | AN18: =-Proforma!E18*Seasonality!$E$5 -> -12705.28 | AO18: =-Proforma!E18*Seasonality!$E$6 -> 0 | AP18: =-Proforma!E18*Seasonality!$E$7 -> -14520.32 | AQ18: =-Proforma!E18*Seasonality!$E$8 -> -1009.616 | AR18: =-Proforma!E18*Seasonality!$E$9 -> 0 | AS18: =-Proforma!E18*Seasonality!$E$10 -> -2609.12 | AT18: =-Proforma!E18*Seasonality!$E$11 -> -36731.872 | AU18: =-Proforma!E18*Seasonality!$E$12 -> -16766.432 | AV18: =-Proforma!E18*Seasonality!$E$13 -> -2472.992 | AW18: =-Proforma!E18*Seasonality!$E$14 -> -9165.952 | AX18: =-Proforma!F18*Seasonality!$E$3 -> -5228.4496 | AY18: =-Proforma!F18*Seasonality!$E$4 -> -13975.808 | AZ18: =-Proforma!F18*Seasonality!$E$5 -> -13975.808 | BA18: =-Proforma!F18*Seasonality!$E$6 -> 0 | BB18: =-Proforma!F18*Seasonality!$E$7 -> -15972.352 | BC18: =-Proforma!F18*Seasonality!$E$8 -> -1110.5776 | BD18: =-Proforma!F18*Seasonality!$E$9 -> 0 | BE18: =-Proforma!F18*Seasonality!$E$10 -> -2870.032 | BF18: =-Proforma!F18*Seasonality!$E$11 -> -40405.059 | BG18: =-Proforma!F18*Seasonality!$E$12 -> -18443.075 | BH18: =-Proforma!F18*Seasonality!$E$13 -> -2720.2912 | BI18: =-Proforma!F18*Seasonality!$E$14 -> -10082.547 | BJ18: =-Proforma!G18*Seasonality!$E$3 -> -5751.2778 | BK18: =-Proforma!G18*Seasonality!$E$4 -> -15373.344 | BL18: =-Proforma!G18*Seasonality!$E$5 -> -15373.344 | BM18: =-Proforma!G18*Seasonality!$E$6 -> 0 | BN18: =-Proforma!G18*Seasonality!$E$7 -> -17569.536 | BO18: =-Proforma!G18*Seasonality!$E$8 -> -1221.6318 | BP18: =-Proforma!G18*Seasonality!$E$9 -> 0 | BQ18: =-Proforma!G18*Seasonality!$E$10 -> -3157.026 | BR18: =-Proforma!G18*Seasonality!$E$11 -> -44445.436 | BS18: =-Proforma!G18*Seasonality!$E$12 -> -20287.324 | BT18: =-Proforma!G18*Seasonality!$E$13 -> -2992.3116 | BU18: =-Proforma!G18*Seasonality!$E$14 -> -11090.77
A19: Marketing — social/digital/natl/dues | B19: 0 | C19: 0 | D19: 0 | E19: 0 | F19: 0 | G19: 0 | H19: 0 | I19: =-(Proforma!B16+Proforma!B17+Proforma!B19)/5-Proforma!B20 -> -16325 | J19: =-(Proforma!B16+Proforma!B17+Proforma!B19)/5 -> -14000 | K19: =-(Proforma!B16+Proforma!B17+Proforma!B19)/5 -> -14000 | L19: =-(Proforma!B16+Proforma!B17+Proforma!B19)/5 -> -14000 | M19: =-(Proforma!B16+Proforma!B17+Proforma!B19)/5 -> -14000 | N19: =-(Proforma!C16+Proforma!C17+Proforma!C19)/12-IF(1=1,Proforma!C20,0) -> -16491.667 | O19: =-(Proforma!C16+Proforma!C17+Proforma!C19)/12-IF(2=1,Proforma!C20,0) -> -14166.667 | P19: =-(Proforma!C16+Proforma!C17+Proforma!C19)/12-IF(3=1,Proforma!C20,0) -> -14166.667 | Q19: =-(Proforma!C16+Proforma!C17+Proforma!C19)/12-IF(4=1,Proforma!C20,0) -> -14166.667 | R19: =-(Proforma!C16+Proforma!C17+Proforma!C19)/12-IF(5=1,Proforma!C20,0) -> -14166.667 | S19: =-(Proforma!C16+Proforma!C17+Proforma!C19)/12-IF(6=1,Proforma!C20,0) -> -14166.667 | T19: =-(Proforma!C16+Proforma!C17+Proforma!C19)/12-IF(7=1,Proforma!C20,0) -> -14166.667 | U19: =-(Proforma!C16+Proforma!C17+Proforma!C19)/12-IF(8=1,Proforma!C20,0) -> -14166.667 | V19: =-(Proforma!C16+Proforma!C17+Proforma!C19)/12-IF(9=1,Proforma!C20,0) -> -14166.667 | W19: =-(Proforma!C16+Proforma!C17+Proforma!C19)/12-IF(10=1,Proforma!C20,0) -> -14166.667 | X19: =-(Proforma!C16+Proforma!C17+Proforma!C19)/12-IF(11=1,Proforma!C20,0) -> -14166.667 | Y19: =-(Proforma!C16+Proforma!C17+Proforma!C19)/12-IF(12=1,Proforma!C20,0) -> -14166.667 | Z19: =-(Proforma!D16+Proforma!D17+Proforma!D19)/12-IF(1=1,Proforma!D20,0) -> -33991.667 | AA19: =-(Proforma!D16+Proforma!D17+Proforma!D19)/12-IF(2=1,Proforma!D20,0) -> -31666.667 | AB19: =-(Proforma!D16+Proforma!D17+Proforma!D19)/12-IF(3=1,Proforma!D20,0) -> -31666.667 | AC19: =-(Proforma!D16+Proforma!D17+Proforma!D19)/12-IF(4=1,Proforma!D20,0) -> -31666.667 | AD19: =-(Proforma!D16+Proforma!D17+Proforma!D19)/12-IF(5=1,Proforma!D20,0) -> -31666.667 | AE19: =-(Proforma!D16+Proforma!D17+Proforma!D19)/12-IF(6=1,Proforma!D20,0) -> -31666.667 | AF19: =-(Proforma!D16+Proforma!D17+Proforma!D19)/12-IF(7=1,Proforma!D20,0) -> -31666.667 | AG19: =-(Proforma!D16+Proforma!D17+Proforma!D19)/12-IF(8=1,Proforma!D20,0) -> -31666.667 | AH19: =-(Proforma!D16+Proforma!D17+Proforma!D19)/12-IF(9=1,Proforma!D20,0) -> -31666.667 | AI19: =-(Proforma!D16+Proforma!D17+Proforma!D19)/12-IF(10=1,Proforma!D20,0) -> -31666.667 | AJ19: =-(Proforma!D16+Proforma!D17+Proforma!D19)/12-IF(11=1,Proforma!D20,0) -> -31666.667 | AK19: =-(Proforma!D16+Proforma!D17+Proforma!D19)/12-IF(12=1,Proforma!D20,0) -> -31666.667 | AL19: =-(Proforma!E16+Proforma!E17+Proforma!E19)/12-IF(1=1,Proforma!E20,0) -> -53158.333 | AM19: =-(Proforma!E16+Proforma!E17+Proforma!E19)/12-IF(2=1,Proforma!E20,0) -> -50833.333 | AN19: =-(Proforma!E16+Proforma!E17+Proforma!E19)/12-IF(3=1,Proforma!E20,0) -> -50833.333 | AO19: =-(Proforma!E16+Proforma!E17+Proforma!E19)/12-IF(4=1,Proforma!E20,0) -> -50833.333 | AP19: =-(Proforma!E16+Proforma!E17+Proforma!E19)/12-IF(5=1,Proforma!E20,0) -> -50833.333 | AQ19: =-(Proforma!E16+Proforma!E17+Proforma!E19)/12-IF(6=1,Proforma!E20,0) -> -50833.333 | AR19: =-(Proforma!E16+Proforma!E17+Proforma!E19)/12-IF(7=1,Proforma!E20,0) -> -50833.333 | AS19: =-(Proforma!E16+Proforma!E17+Proforma!E19)/12-IF(8=1,Proforma!E20,0) -> -50833.333 | AT19: =-(Proforma!E16+Proforma!E17+Proforma!E19)/12-IF(9=1,Proforma!E20,0) -> -50833.333 | AU19: =-(Proforma!E16+Proforma!E17+Proforma!E19)/12-IF(10=1,Proforma!E20,0) -> -50833.333 | AV19: =-(Proforma!E16+Proforma!E17+Proforma!E19)/12-IF(11=1,Proforma!E20,0) -> -50833.333 | AW19: =-(Proforma!E16+Proforma!E17+Proforma!E19)/12-IF(12=1,Proforma!E20,0) -> -50833.333 | AX19: =-(Proforma!F16+Proforma!F17+Proforma!F19)/12-IF(1=1,Proforma!F20,0) -> -69825 | AY19: =-(Proforma!F16+Proforma!F17+Proforma!F19)/12-IF(2=1,Proforma!F20,0) -> -67500 | AZ19: =-(Proforma!F16+Proforma!F17+Proforma!F19)/12-IF(3=1,Proforma!F20,0) -> -67500 | BA19: =-(Proforma!F16+Proforma!F17+Proforma!F19)/12-IF(4=1,Proforma!F20,0) -> -67500 | BB19: =-(Proforma!F16+Proforma!F17+Proforma!F19)/12-IF(5=1,Proforma!F20,0) -> -67500 | BC19: =-(Proforma!F16+Proforma!F17+Proforma!F19)/12-IF(6=1,Proforma!F20,0) -> -67500 | BD19: =-(Proforma!F16+Proforma!F17+Proforma!F19)/12-IF(7=1,Proforma!F20,0) -> -67500 | BE19: =-(Proforma!F16+Proforma!F17+Proforma!F19)/12-IF(8=1,Proforma!F20,0) -> -67500 | BF19: =-(Proforma!F16+Proforma!F17+Proforma!F19)/12-IF(9=1,Proforma!F20,0) -> -67500 | BG19: =-(Proforma!F16+Proforma!F17+Proforma!F19)/12-IF(10=1,Proforma!F20,0) -> -67500 | BH19: =-(Proforma!F16+Proforma!F17+Proforma!F19)/12-IF(11=1,Proforma!F20,0) -> -67500 | BI19: =-(Proforma!F16+Proforma!F17+Proforma!F19)/12-IF(12=1,Proforma!F20,0) -> -67500 | BJ19: =-(Proforma!G16+Proforma!G17+Proforma!G19)/12-IF(1=1,Proforma!G20,0) -> -82325 | BK19: =-(Proforma!G16+Proforma!G17+Proforma!G19)/12-IF(2=1,Proforma!G20,0) -> -80000 | BL19: =-(Proforma!G16+Proforma!G17+Proforma!G19)/12-IF(3=1,Proforma!G20,0) -> -80000 | BM19: =-(Proforma!G16+Proforma!G17+Proforma!G19)/12-IF(4=1,Proforma!G20,0) -> -80000 | BN19: =-(Proforma!G16+Proforma!G17+Proforma!G19)/12-IF(5=1,Proforma!G20,0) -> -80000 | BO19: =-(Proforma!G16+Proforma!G17+Proforma!G19)/12-IF(6=1,Proforma!G20,0) -> -80000 | BP19: =-(Proforma!G16+Proforma!G17+Proforma!G19)/12-IF(7=1,Proforma!G20,0) -> -80000 | BQ19: =-(Proforma!G16+Proforma!G17+Proforma!G19)/12-IF(8=1,Proforma!G20,0) -> -80000 | BR19: =-(Proforma!G16+Proforma!G17+Proforma!G19)/12-IF(9=1,Proforma!G20,0) -> -80000 | BS19: =-(Proforma!G16+Proforma!G17+Proforma!G19)/12-IF(10=1,Proforma!G20,0) -> -80000 | BT19: =-(Proforma!G16+Proforma!G17+Proforma!G19)/12-IF(11=1,Proforma!G20,0) -> -80000 | BU19: =-(Proforma!G16+Proforma!G17+Proforma!G19)/12-IF(12=1,Proforma!G20,0) -> -80000
A20: One-time launch capital | B20: 0 | C20: 0 | D20: 0 | E20: 0 | F20: 0 | G20: 0 | H20: 0 | I20: =-Proforma!B21/3 -> -40000 | J20: =-Proforma!B21/3 -> -40000 | K20: =-Proforma!B21/3 -> -40000 | L20: 0 | M20: 0 | N20: 0 | O20: 0 | P20: 0 | Q20: 0 | R20: 0 | S20: 0 | T20: 0 | U20: 0 | V20: 0 | W20: 0 | X20: 0 | Y20: 0 | Z20: 0 | AA20: 0 | AB20: 0 | AC20: 0 | AD20: 0 | AE20: 0 | AF20: 0 | AG20: 0 | AH20: 0 | AI20: 0 | AJ20: 0 | AK20: 0 | AL20: 0 | AM20: 0 | AN20: 0 | AO20: 0 | AP20: 0 | AQ20: 0 | AR20: 0 | AS20: 0 | AT20: 0 | AU20: 0 | AV20: 0 | AW20: 0 | AX20: 0 | AY20: 0 | AZ20: 0 | BA20: 0 | BB20: 0 | BC20: 0 | BD20: 0 | BE20: 0 | BF20: 0 | BG20: 0 | BH20: 0 | BI20: 0 | BJ20: 0 | BK20: 0 | BL20: 0 | BM20: 0 | BN20: 0 | BO20: 0 | BP20: 0 | BQ20: 0 | BR20: 0 | BS20: 0 | BT20: 0 | BU20: 0
A21: G&A | B21: 0 | C21: 0 | D21: 0 | E21: 0 | F21: 0 | G21: 0 | H21: 0 | I21: =-Proforma!B25/5 -> -30000 | J21: =-Proforma!B25/5 -> -30000 | K21: =-Proforma!B25/5 -> -30000 | L21: =-Proforma!B25/5 -> -30000 | M21: =-Proforma!B25/5 -> -30000 | N21: =-Proforma!C25/12 -> -26666.667 | O21: =-Proforma!C25/12 -> -26666.667 | P21: =-Proforma!C25/12 -> -26666.667 | Q21: =-Proforma!C25/12 -> -26666.667 | R21: =-Proforma!C25/12 -> -26666.667 | S21: =-Proforma!C25/12 -> -26666.667 | T21: =-Proforma!C25/12 -> -26666.667 | U21: =-Proforma!C25/12 -> -26666.667 | V21: =-Proforma!C25/12 -> -26666.667 | W21: =-Proforma!C25/12 -> -26666.667 | X21: =-Proforma!C25/12 -> -26666.667 | Y21: =-Proforma!C25/12 -> -26666.667 | Z21: =-Proforma!D25/12 -> -48333.333 | AA21: =-Proforma!D25/12 -> -48333.333 | AB21: =-Proforma!D25/12 -> -48333.333 | AC21: =-Proforma!D25/12 -> -48333.333 | AD21: =-Proforma!D25/12 -> -48333.333 | AE21: =-Proforma!D25/12 -> -48333.333 | AF21: =-Proforma!D25/12 -> -48333.333 | AG21: =-Proforma!D25/12 -> -48333.333 | AH21: =-Proforma!D25/12 -> -48333.333 | AI21: =-Proforma!D25/12 -> -48333.333 | AJ21: =-Proforma!D25/12 -> -48333.333 | AK21: =-Proforma!D25/12 -> -48333.333 | AL21: =-Proforma!E25/12 -> -73333.333 | AM21: =-Proforma!E25/12 -> -73333.333 | AN21: =-Proforma!E25/12 -> -73333.333 | AO21: =-Proforma!E25/12 -> -73333.333 | AP21: =-Proforma!E25/12 -> -73333.333 | AQ21: =-Proforma!E25/12 -> -73333.333 | AR21: =-Proforma!E25/12 -> -73333.333 | AS21: =-Proforma!E25/12 -> -73333.333 | AT21: =-Proforma!E25/12 -> -73333.333 | AU21: =-Proforma!E25/12 -> -73333.333 | AV21: =-Proforma!E25/12 -> -73333.333 | AW21: =-Proforma!E25/12 -> -73333.333 | AX21: =-Proforma!F25/12 -> -104166.67 | AY21: =-Proforma!F25/12 -> -104166.67 | AZ21: =-Proforma!F25/12 -> -104166.67 | BA21: =-Proforma!F25/12 -> -104166.67 | BB21: =-Proforma!F25/12 -> -104166.67 | BC21: =-Proforma!F25/12 -> -104166.67 | BD21: =-Proforma!F25/12 -> -104166.67 | BE21: =-Proforma!F25/12 -> -104166.67 | BF21: =-Proforma!F25/12 -> -104166.67 | BG21: =-Proforma!F25/12 -> -104166.67 | BH21: =-Proforma!F25/12 -> -104166.67 | BI21: =-Proforma!F25/12 -> -104166.67 | BJ21: =-Proforma!G25/12 -> -137500 | BK21: =-Proforma!G25/12 -> -137500 | BL21: =-Proforma!G25/12 -> -137500 | BM21: =-Proforma!G25/12 -> -137500 | BN21: =-Proforma!G25/12 -> -137500 | BO21: =-Proforma!G25/12 -> -137500 | BP21: =-Proforma!G25/12 -> -137500 | BQ21: =-Proforma!G25/12 -> -137500 | BR21: =-Proforma!G25/12 -> -137500 | BS21: =-Proforma!G25/12 -> -137500 | BT21: =-Proforma!G25/12 -> -137500 | BU21: =-Proforma!G25/12 -> -137500
A22: TOTAL COSTS | B22: =SUM(B13:B21) -> 0 | C22: =SUM(C13:C21) -> 0 | D22: =SUM(D13:D21) -> 0 | E22: =SUM(E13:E21) -> 0 | F22: =SUM(F13:F21) -> 0 | G22: =SUM(G13:G21) -> 0 | H22: =SUM(H13:H21) -> 0 | I22: =SUM(I13:I21) -> -136571.73 | ... BU22: =SUM(BU13:BU21) -> -1121460.2
A24: NET (EBITDA) | B24: =B11+B22 -> 0 | C24: =C11+C22 -> 0 | D24: =D11+D22 -> 0 | E24: =E11+E22 -> 0 | F24: =F11+F22 -> 0 | G24: =G11+G22 -> 0 | H24: =H11+H22 -> 0 | I24: =I11+I22 -> -136571.73 | ... BU24: =BU11+BU22 -> 643071.05
A25: CUMULATIVE CASH | B25: =B24 -> 0 | C25: =B25+C24 -> 0 | D25: =C25+D24 -> 0 | E25: =D25+E24 -> 0 | F25: =E25+F24 -> 0 | G25: =F25+G24 -> 0 | H25: =G25+H24 -> 0 | I25: =H25+I24 -> -136571.73 | J25: =I25+J24 -> -294429.89 | ... BU25: =BT25+BU24 -> 53963015
A26: CASH ON HAND (incl. investment) | B26: =Proforma!$J$18+B25 | C26: =Proforma!$J$18+C25 | D26: =Proforma!$J$18+D25 | E26: =Proforma!$J$18+E25 | F26: =Proforma!$J$18+F25 | G26: =Proforma!$J$18+G25 | H26: =Proforma!$J$18+H25 | I26: =Proforma!$J$18+I25 | ... BU26: =Proforma!$J$18+BU25
A27: Peak operating cash need (deepest cumulative trough) | B27: =-MIN(B25:BU25) -> 797227.47
A28: Trough month (lowest cash point) | B28: =INDEX(5:5,1,MATCH(MIN(B25:BU25),B25:BU25,0)+1)&" "&INDEX(4:4,1,12*INT((MATCH(MIN(B25:BU25),B25:BU25,0)-1)/12)+2) -> Mar 2027

Sheet Events
A2: EVENTS — Plan & Budget (combined)
A3: Toggle Include? = Y/N to add/remove an event; travel costs auto-calc from the assumptions; Capital Summary updates live. Blue = editable input.
A4: ASSUMPTIONS (drive travel costs)
A5: People attending | B5: 3
A6: People per room | B6: 2
A7: Lodging $/room/night | B7: 160
A8: Per diem $/person/day | B8: 40
A9: Mileage $/mile | B9: 0.7
A10: Rooms (auto) | B10: =ROUNDUP(B5/B6,0) -> 2
A12: Event | B12: Include? | C12: Tier | D12: Date | E12: Location | F12: Attendance | G12: Strategic value | H12: Booth/Reg $ | I12: RT Miles | J12: Days | K12: Nights | L12: Mileage $ | M12: Lodging $ | N12: Per Diem $ | O12: Event Total | P12: Link
A13: Nebraska Ag & Spray Drone Conference | B13: Y | C13: Top | D13: Aug 21-22, 2026 | E13: Norfolk, NE | F13: ~1,500 (industry) | G13: Spray drones, aerial application, regs, innovation | H13: 500 | I13: 940 | J13: 3 | K13: 2 | L13: =I13*$B$9 -> 658 | M13: =K13*$B$10*$B$7 -> 640 | N13: =J13*$B$5*$B$8 -> 360 | O13: =IF($B13="Y",H13+L13+M13+N13,0) -> 2158 | P13: cropwatch.unl.edu
A14: Farm Progress Show | B14: Y | C14: Top | D14: Sept 1-3, 2026 | E14: Boone, IA | F14: ~100,000+ (biennial) | G14: Row crops, equipment, precision ag; Drone Zone demos | H14: 4500 | I14: 1300 | J14: 5 | K14: 4 | L14: =I14*$B$9 -> 910 | M14: =K14*$B$10*$B$7 -> 1280 | N14: =J14*$B$5*$B$8 -> 600 | O14: =IF($B14="Y",H14+L14+M14+N14,0) -> 7290 | P14: farmprogressshow.com
A15: Commercial UAV Expo Americas | B15: Y | C15: Strong | D15: Sept 1-3, 2026 | E15: Las Vegas, NV | F15: ~4,000; 225+ exhibitors | G15: UAV tech across sectors incl. agriculture | H15: 6000 | I15: 1500 | J15: 5 | K15: 4 | L15: =I15*$B$9 -> 1050 | M15: =K15*$B$10*$B$7 -> 1280 | N15: =J15*$B$5*$B$8 -> 600 | O15: =IF($B15="Y",H15+L15+M15+N15,0) -> 8930 | P15: expouav.com
A16: Husker Harvest Days | B16: Y | C16: Strong | D16: Sept 15-17, 2026 | E16: Grand Island, NE | F16: ~100,000 | G16: Row crops, irrigation, equipment, technology | H16: 4000 | I16: 800 | J16: 4 | K16: 3 | L16: =I16*$B$9 -> 560 | M16: =K16*$B$10*$B$7 -> 960 | N16: =J16*$B$5*$B$8 -> 480 | O16: =IF($B16="Y",H16+L16+M16+N16,0) -> 6000 | P16: huskerharvestdays.com
A17: Farm Science Review | B17: Y | C17: Strong | D17: Sept 22-24, 2026 | E17: London, OH | F17: ~140,000 | G17: Crop production, precision ag, equipment | H17: 4000 | I17: 2600 | J17: 6 | K17: 5 | L17: =I17*$B$9 -> 1820 | M17: =K17*$B$10*$B$7 -> 1600 | N17: =J17*$B$5*$B$8 -> 720 | O17: =IF($B17="Y",H17+L17+M17+N17,0) -> 8140 | P17: fsr.osu.edu/exhibitors
A18: Ozark Fall Farmfest | B18: Y | C18: Optional | D18: Oct 2-4, 2026 | E18: Springfield, MO | F18: ~50,000 | G18: General agriculture, equipment, services | H18: 2000 | I18: 1600 | J18: 5 | K18: 4 | L18: =I18*$B$9 -> 1120 | M18: =K18*$B$10*$B$7 -> 1280 | N18: =J18*$B$5*$B$8 -> 600 | O18: =IF($B18="Y",H18+L18+M18+N18,0) -> 5000 | P18: ozarkfallfarmfest.com
A19: Sunbelt Ag Expo | B19: Y | C19: Strong | D19: Oct 20-22, 2026 | E19: Moultrie, GA | F19: ~100,000 | G19: Row/specialty crops, equipment, livestock | H19: 4000 | I19: 3000 | J19: 7 | K19: 6 | L19: =I19*$B$9 -> 2100 | M19: =K19*$B$10*$B$7 -> 1920 | N19: =J19*$B$5*$B$8 -> 840 | O19: =IF($B19="Y",H19+L19+M19+N19,0) -> 8860 | P19: sunbeltexpo.com/exhibitors
A20: Colorado AAA Convention (CoAAA) | B20: Y | C20: Top | D20: Early Nov 2026 | E20: Lamar, CO | F20: CO aerial applicators & ag pilots | G20: Aerial application, crop dusting, spray drones, regs; Fly-In | H20: 750 | I20: 420 | J20: 3 | K20: 2 | L20: =I20*$B$9 -> 294 | M20: =K20*$B$10*$B$7 -> 640 | N20: =J20*$B$5*$B$8 -> 360 | O20: =IF($B20="Y",H20+L20+M20+N20,0) -> 2044 | P20: coagav.org/events
A21: Western CO Farm & Ranch Innovation Expo | B21: Y | C21: Top | D21: Nov 13-15, 2026 | E21: Montrose, CO | F21: Regional (Western Slope) | G21: Soil health, water, livestock, equipment demos | H21: 300 | I21: 640 | J21: 4 | K21: 3 | L21: =I21*$B$9 -> 448 | M21: =K21*$B$10*$B$7 -> 960 | N21: =J21*$B$5*$B$8 -> 480 | O21: =IF($B21="Y",H21+L21+M21+N21,0) -> 2188 | P21: shavanocd.org
A22: NAAA Ag Aviation Expo | B22: Y | C22: Top | D22: Nov 16-18, 2026 | E22: Savannah, GA | F22: Aerial applicators nationwide | G22: Aerial application, crop dusting, spray drones, regs | H22: 2500 | I22: 3300 | J22: 7 | K22: 6 | L22: =I22*$B$9 -> 2310 | M22: =K22*$B$10*$B$7 -> 1920 | N22: =J22*$B$5*$B$8 -> 840 | O22: =IF($B22="Y",H22+L22+M22+N22,0) -> 7570 | P22: agaviation.org
A23: National Western Stock Show | B23: Y | C23: Optional | D23: Jan 9-24, 2027 | E23: Denver, CO | F23: ~700,000 | G23: Livestock, ranching, ag heritage, trade show | H23: 2500 | I23: 30 | J23: 1 | K23: 0 | L23: =I23*$B$9 -> 21 | M23: =K23*$B$10*$B$7 -> 0 | N23: =J23*$B$5*$B$8 -> 120 | O23: =IF($B23="Y",H23+L23+M23+N23,0) -> 2641 | P23: nationalwestern.com
A24: Colorado Farm Show | B24: Y | C24: Strong | D24: Jan 26-28, 2027 | E24: Greeley, CO | F24: ~30,000; 300+ exhibitors | G24: Row crops, livestock, equipment, water, precision ag | H24: 700 | I24: 330 | J24: 3 | K24: 0 | L24: =I24*$B$9 -> 231 | M24: =K24*$B$10*$B$7 -> 0 | N24: =J24*$B$5*$B$8 -> 360 | O24: =IF($B24="Y",H24+L24+M24+N24,0) -> 1291 | P24: coloradofarmshow.com
... A30: CSU Wheat Field Days | B30: Y | C30: Optional | D30: June 2027 | E30: Eastern CO trial sites | F30: Growers & agronomists | G30: Wheat variety trials, agronomy, applied research | H30: 500 | I30: 300 | J30: 1 | K30: 0 | L30: =I30*$B$9 -> 210 | M30: =K30*$B$10*$B$7 -> 0 | N30: =J30*$B$5*$B$8 -> 120 | O30: =IF($B30="Y",H30+L30+M30+N30,0) -> 830 | P30: agsci.colostate.edu/wheat
A31: TOTAL — INCLUDED EVENTS | B31: =COUNTIF(B13:B30,"Y")&" of 18" -> 18 of 18 | H31: =SUMIF($B13:$B30,"Y",H13:H30) -> 46550 | L31: =SUMIF($B13:$B30,"Y",L13:L30) -> 17962 | M31: =SUMIF($B13:$B30,"Y",M13:M30) -> 19520 | N31: =SUMIF($B13:$B30,"Y",N13:N30) -> 9720 | O31: =SUMIF($B13:$B30,"Y",O13:O30) -> 93752
A33: ONE-TIME / CAPITAL COSTS (launch — paid once)
A34: Item | B34: Include? | C34: Cost $
A35: Wrapped truck (vehicle wrap + branding; event travel + customer engagement) | B35: Y | C35: 60000
A36: Equipment trailer (haul booth + gear to conventions) | B36: Y | C36: 15000
A37: Merch / giveaways (hats, koozies, samples, swag) | B37: Y | C37: 15000
A38: Booth build / modular display system | B38: Y | C38: 30000
A39: TOTAL — ONE-TIME / CAPITAL | B39: =COUNTIF(B35:B38,"Y")&" of 4" -> 4 of 4 | C39: =SUMIF($B35:$B38,"Y",C35:C38) -> 120000

Sheet Orgs & Boards
A2: ORGS & BOARDS — Plan & Dues (combined)
A3: Toggle Include? = Y/N; dues total flows to the Capital Summary. Blue = editable input.
A4: Organization | B4: Include? | C4: Priority | D4: Annual Dues $ | E4: Type | F4: Who You'll Meet | G4: Board / Leadership Path | H4: How to Get Involved (Next Step) | I4: Link
A5: Colorado Agricultural Aviation Association (CoAAA) | B5: Y | C5: HIGH | D5: 250 | E5: State trade assoc — aerial + drone applicators | F5: Aerial applicators, ag pilots, agronomists, crop consultants, vendors | G5: Board seats require a VOTING membership; max 2 voting/company. Realistic board path. | H5: Join as Allied Trades; attend annual convention; volunteer for a committee, then stand for the board. | I5: coagav.org/join-us
A6: National Ag Aviation Assoc (NAAA) — UAAS Committee | B6: Y | C6: HIGH | D6: 450 | E6: National trade assoc + drone/crewed committee | F6: 1,600+ members in 46 states: applicators, pilots, manufacturers | G6: UAAS Committee = national table where crewed+drone applicators set policy. Seek a seat. | H6: Join NAAA; join the UAAS Committee; attend Ag Aviation Expo (Savannah Nov 16-18). | I6: agaviation.org/membership
A7: Rocky Mountain Agribusiness Association (RMAA) | B7: Y | C7: HIGH | D7: 350 | E7: Regional ag-retail / chemical & fertilizer trade assoc | F7: Chemical & fertilizer cos, ag retailers, grain/feed — the application channel | G7: Active members serve on committees and the board. | H7: Join; attend the January conference & trade show; pitch drone application to ag retailers. | I7: rmagbiz.org/membership
A8: Colorado Farm Bureau (+ county chapters & YF&R) | B8: Y | C8: HIGH | D8: 60 | E8: General farm membership org | F8: Farmers & ranchers statewide and county-level; policy makers | G8: County -> district -> state board ladder. YF&R one seat/district (18-35). | H8: Join; attend your COUNTY meetings; run for a county board seat. | I8: coloradofarmbureau.com/join
A9: Colorado Dept of Ag — Advisory Committees & Ag Commission | B9: Y | C9: HIGH | D9: 0 | E9: State government boards/commissions | F9: Ag leaders, regulators, weed/herbicide pros, commodity reps | G9: Apply anytime. Noxious Weed Advisory Committee overlaps herbicide application. Ag Commission = 9 governor seats. | H9: Apply to the Noxious Weed Advisory Committee; submit a Boards & Commissions app. | I9: ag.colorado.gov/boards-and-commissions
A10: Colorado Corn (Growers Assoc + Admin Committee) | B10: Y | C10: MED | D10: 50 | E10: Commodity organization | F10: Corn growers, row-crop decision-makers, ag-tech partners | G10: Growers Assoc board + checkoff Administrative Committee seats. | H10: Join the Growers Association; attend events; build toward a committee role. | I10: coloradocorn.com/events
A11: Colorado Wheat (Assoc of Wheat Growers + Admin Cmte) | B11: Y | C11: MED | D11: 50 | E11: Commodity organization | F11: Wheat growers and agronomists across the Eastern Plains | G11: Association board + Wheat Administrative Committee seats. | H11: Join; attend CSU wheat field days & wheat events; network toward a seat. | I11: coloradowheat.org
A12: Colorado Weed Management Association (CWMA) | B12: Y | C12: MED | D12: 75 | E12: Professional / applicator network (501c3) | F12: Commercial & private applicators, weed-mgmt pros, agencies | G12: Member-led board and committees; volunteer-friendly. | H12: Join; attend annual conference; position drone application as a weed-control tool. | I12: cwma.org
A13: Local Conservation District / NRCS Working Group | B13: Y | C13: MED | D13: 0 | E13: Local government / producer advisory | F13: Local farmers/ranchers, soil-health & water leaders, NRCS staff | G13: Elected/appointed supervisor seats; Local Working Group shapes funding. | H13: Attend your county conservation district meetings; run for a supervisor seat. | I13: Search "[county] Conservation District CO"
A14: Drone Service Providers Alliance (DSPA) | B14: Y | C14: MED | D14: 240 | E14: National drone-operator advocacy (CO-based) | F14: Small/mid drone service providers, drone-policy advocates | G14: Member-driven; volunteer for working groups. | H14: Join online; engage FAA/Part-137 advocacy. | I14: dspalliance.org/join-us
A15: Commercial Drone Alliance | B15: Y | C15: LOW | D15: 500 | E15: National enterprise drone policy advocacy | F15: Enterprise drone operators, manufacturers, policy stakeholders | G15: Committees/working groups for members. | H15: Join if pursuing national policy visibility or enterprise partnerships. | I15: commercialdronealliance.org
A16: Certified Crop Adviser (CCA) credential | B16: Y | C16: LOW | D16: 300 | E16: Professional certification | F16: Agronomists, crop consultants, applicators (in CE settings) | G16: Not a board, but credibility currency for agronomy tables. | H16: Pursue the CCA credential to gain standing with applicators. | I16: certifiedcropadviser.org
A17: TOTAL — INCLUDED MEMBERSHIPS | B17: =COUNTIF(B5:B16,"Y")&" of 12" -> 12 of 12 | D17: =SUMIF($B5:$B16,"Y",D5:D16) -> 2325

Sheet Capital Summary
A2: CLOUD COWBOY — YEAR 1 CAPITAL SUMMARY
A3: Live totals — edit any blue input or toggle on the Events / Orgs & Boards tabs and everything here updates. Green = pulled from other tabs.
A4: A. EVENT COSTS
A5: Booth / registration (included events) | B5: =Events!H31 -> 46550
A6: Mileage (driving) | B6: =Events!L31 -> 17962
A7: Lodging | B7: =Events!M31 -> 19520
A8: Per diem (meals) | B8: =Events!N31 -> 9720
A9: Events subtotal | B9: =Events!O31 -> 93752
A11: B. MEMBERSHIPS & DUES
A12: Memberships subtotal (annual) | B12: ='Orgs & Boards'!D17 -> 2325
A14: C. ONE-TIME / CAPITAL (from Events tab)
A15: Wrapped truck (wrap + branding; event travel + customer engagement) | B15: =Events!C35 -> 60000
A16: Equipment trailer (haul booth + gear) | B16: =Events!C36 -> 15000
A17: Merch / giveaways (swag, samples) | B17: =Events!C37 -> 15000
A18: Booth build / modular display system | B18: =Events!C38 -> 30000
A19: One-time / capital subtotal | B19: =SUM(B15:B18) -> 120000
A21: D. CONTINGENCY
A22: Contingency % | C22: 0.1
A23: Contingency $ | B23: =(B9+B12+B19)*C22 -> 21607.7
A25: GRAND TOTAL — YEAR 1 | B25: =B9+B12+B19+B23 -> 237684.7
A28: EVENT SPEND BY PRIORITY TIER (included events only)
A29: Tier | B29: Event Total | C29: # Events
A30: Top | B30: =SUMIFS(Events!O13:O30,Events!C13:C30,"Top",Events!B13:B30,"Y") -> 27850 | C30: =COUNTIFS(Events!C13:C30,"Top",Events!B13:B30,"Y") -> 6
A31: Strong | B31: =SUMIFS(Events!O13:O30,Events!C13:C30,"Strong",Events!B13:B30,"Y") -> 43569 | C31: =COUNTIFS(Events!C13:C30,"Strong",Events!B13:B30,"Y") -> 7
A32: Optional | B32: =SUMIFS(Events!O13:O30,Events!C13:C30,"Optional",Events!B13:B30,"Y") -> 22333 | C32: =COUNTIFS(Events!C13:C30,"Optional",Events!B13:B30,"Y") -> 5
